Workbook

Sheet Sheet1
C8: 255 | D8: 255 | E8: 255 | F8: 0 | G8: 0 | H8: 0 | I8: 0 | J8: 0 | K8: 0 | L8: 0 | M8: 0 | N8: 0 | O8: 0 | P8: 255 | Q8: 0 | R8: 0 | S8: 0 | T8: 0 | U8: 0 | V8: 0 | W8: 0 | X8: 0 | Y8: 0 | Z8: 0 | AA8: 0 | AB8: 0 | AC8: 0 | AD8: 255 | AE8: 255 | AF8: 255
C9: 255 | D9: 255 | E9: 255 | F9: 0 | G9: 0 | H9: 0 | I9: 0 | J9: 0 | K9: 0 | L9: 0 | M9: 0 | N9: 0 | O9: 0 | P9: 255 | Q9: 0 | R9: 0 | S9: 0 | T9: 0 | U9: 0 | V9: 0 | W9: 0 | X9: 0 | Y9: 0 | Z9: 0 | AA9: 0 | AB9: 0 | AC9: 0 | AD9: 255 | AE9: 255 | AF9: 255
C10: 255 | D10: 255 | E10: 255 | F10: 0 | G10: 0 | H10: 0 | I10: 0 | J10: 0 | K10: 0 | L10: 0 | M10: 0 | N10: 0 | O10: 255 | P10: 255 | Q10: 255 | R10: 0 | S10: 0 | T10: 0 | U10: 0 | V10: 0 | W10: 0 | X10: 255 | Y10: 255 | Z10: 255 | AA10: 255 | AB10: 255 | AC10: 255 | AD10: 255 | AE10: 255 | AF10: 255
C11: 0 | D11: 0 | E11: 0 | F11: 0 | G11: 0 | H11: 0 | I11: 0 | J11: 0 | K11: 0 | L11: 0 | M11: 0 | N11: 0 | O11: 255 | P11: 255 | Q11: 255 | R11: 0 | S11: 0 | T11: 0 | U11: 0 | V11: 0 | W11: 0 | X11: 255 | Y11: 255 | Z11: 255 | AA11: 255 | AB11: 255 | AC11: 255 | AD11: 255 | AE11: 0 | AF11: 0
C12: 0 | D12: 0 | E12: 0 | F12: 0 | G12: 0 | H12: 0 | I12: 0 | J12: 0 | K12: 0 | L12: 0 | M12: 0 | N12: 0 | O12: 255 | P12: 255 | Q12: 255 | R12: 0 | S12: 0 | T12: 0 | U12: 0 | V12: 0 | W12: 0 | X12: 255 | Y12: 255 | Z12: 255 | AA12: 255 | AB12: 255 | AC12: 255 | AD12: 255 | AE12: 0 | AF12: 0
C13: 0 | D13: 0 | E13: 0 | F13: 0 | G13: 0 | H13: 0 | I13: 0 | J13: 0 | K13: 0 | L13: 0 | M13: 0 | N13: 0 | O13: 255 | P13: 255 | Q13: 255 | R13: 0 | S13: 0 | T13: 0 | U13: 0 | V13: 0 | W13: 0 | X13: 255 | Y13: 255 | Z13: 255 | AA13: 255 | AB13: 255 | AC13: 255 | AD13: 255 | AE13: 0 | AF13: 0
C14: 0 | D14: 0 | E14: 0 | F14: 0 | G14: 0 | H14: 0 | I14: 0 | J14: 0 | K14: 0 | L14: 0 | M14: 0 | N14: 0 | O14: 0 | P14: 255 | Q14: 0 | R14: 0 | S14: 0 | T14: 0 | U14: 0 | V14: 0 | W14: 0 | X14: 255 | Y14: 255 | Z14: 255 | AA14: 255 | AB14: 255 | AC14: 255 | AD14: 255 | AE14: 0 | AF14: 0
C15: 0 | D15: 0 | E15: 0 | F15: 0 | G15: 0 | H15: 0 | I15: 255 | J15: 0 | K15: 0 | L15: 0 | M15: 0 | N15: 0 | O15: 0 | P15: 255 | Q15: 0 | R15: 0 | S15: 0 | T15: 0 | U15: 0 | V15: 0 | W15: 0 | X15: 255 | Y15: 255 | Z15: 255 | AA15: 255 | AB15: 255 | AC15: 255 | AD15: 255 | AE15: 0 | AF15: 0
C16: 0 | D16: 0 | E16: 0 | F16: 0 | G16: 0 | H16: 255 | I16: 0 | J16: 255 | K16: 0 | L16: 0 | M16: 0 | N16: 0 | O16: 0 | P16: 255 | Q16: 0 | R16: 0 | S16: 0 | T16: 0 | U16: 0 | V16: 0 | W16: 0 | X16: 255 | Y16: 255 | Z16: 255 | AA16: 255 | AB16: 255 | AC16: 255 | AD16: 255 | AE16: 0 | AF16: 0
C17: 0 | D17: 0 | E17: 0 | F17: 0 | G17: 255 | H17: 0 | I17: 0 | J17: 0 | K17: 255 | L17: 0 | M17: 0 | N17: 0 | O17: 0 | P17: 255 | Q17: 0 | R17: 0 | S17: 0 | T17: 0 | U17: 0 | V17: 0 | W17: 0 | X17: 255 | Y17: 255 | Z17: 255 | AA17: 255 | AB17: 255 | AC17: 255 | AD17: 255 | AE17: 0 | AF17: 0
C18: 0 | D18: 0 | E18: 0 | F18: 255 | G18: 0 | H18: 0 | I18: 0 | J18: 0 | K18: 0 | L18: 255 | M18: 255 | N18: 255 | O18: 255 | P18: 255 | Q18: 255 | R18: 255 | S18: 255 | T18: 0 | U18: 0 | V18: 0 | W18: 0 | X18: 255 | Y18: 255 | Z18: 255 | AA18: 255 | AB18: 255 | AC18: 255 | AD18: 255 | AE18: 0 | AF18: 0
C19: 0 | D19: 0 | E19: 255 | F19: 0 | G19: 0 | H19: 0 | I19: 0 | J19: 0 | K19: 0 | L19: 0 | M19: 255 | N19: 255 | O19: 255 | P19: 255 | Q19: 255 | R19: 255 | S19: 255 | T19: 0 | U19: 0 | V19: 0 | W19: 0 | X19: 0 | Y19: 0 | Z19: 0 | AA19: 0 | AB19: 0 | AC19: 0 | AD19: 0 | AE19: 0 | AF19: 0
... C37: 0 | D37: 0 | E37: 0 | F37: 0 | G37: 0 | H37: 255 | I37: 0 | J37: 0 | K37: 0 | L37: 0 | M37: 255 | N37: 255 | O37: 255 | P37: 255 | Q37: 255 | R37: 255 | S37: 255 | T37: 0 | U37: 0 | V37: 0 | W37: 255 | X37: 0 | Y37: 0 | Z37: 0 | AA37: 0 | AB37: 0 | AC37: 0 | AD37: 0 | AE37: 0 | AF37: 0

Sheet Sheet2
B1: kernel
B2: -1 | C2: 0 | D2: 1 | G2: =MAX(0,MIN(255,SUMPRODUCT(Sheet1!C8:E10,$B$2:$D$4))) -> 0 | H2: =MAX(0,MIN(255,SUMPRODUCT(Sheet1!D8:F10,$B$2:$D$4))) -> 0 | I2: =MAX(0,MIN(255,SUMPRODUCT(Sheet1!E8:G10,$B$2:$D$4))) -> 0 | J2: =MAX(0,MIN(255,SUMPRODUCT(Sheet1!F8:H10,$B$2:$D$4))) -> 0 | K2: =MAX(0,MIN(255,SUMPRODUCT(Sheet1!G8:I10,$B$2:$D$4))) -> 0 | L2: =MAX(0,MIN(255,SUMPRODUCT(Sheet1!H8:J10,$B$2:$D$4))) -> 0 | M2: =MAX(0,MIN(255,SUMPRODUCT(Sheet1!I8:K10,$B$2:$D$4))) -> 0 | N2: =MAX(0,MIN(255,SUMPRODUCT(Sheet1!J8:L10,$B$2:$D$4))) -> 0 | ... AH2: =MAX(0,MIN(255,SUMPRODUCT(Sheet1!AD8:AF10,$B$2:$D$4))) -> 0
B3: -1 | C3: 0 | D3: 1 | G3: =MAX(0,MIN(255,SUMPRODUCT(Sheet1!C9:E11,$B$2:$D$4))) -> 0 | H3: =MAX(0,MIN(255,SUMPRODUCT(Sheet1!D9:F11,$B$2:$D$4))) -> 0 | I3: =MAX(0,MIN(255,SUMPRODUCT(Sheet1!E9:G11,$B$2:$D$4))) -> 0 | J3: =MAX(0,MIN(255,SUMPRODUCT(Sheet1!F9:H11,$B$2:$D$4))) -> 0 | K3: =MAX(0,MIN(255,SUMPRODUCT(Sheet1!G9:I11,$B$2:$D$4))) -> 0 | L3: =MAX(0,MIN(255,SUMPRODUCT(Sheet1!H9:J11,$B$2:$D$4))) -> 0 | M3: =MAX(0,MIN(255,SUMPRODUCT(Sheet1!I9:K11,$B$2:$D$4))) -> 0 | N3: =MAX(0,MIN(255,SUMPRODUCT(Sheet1!J9:L11,$B$2:$D$4))) -> 0 | ... AH3: =MAX(0,MIN(255,SUMPRODUCT(Sheet1!AD9:AF11,$B$2:$D$4))) -> 0
B4: -1 | C4: 0 | D4: 1 | G4: =MAX(0,MIN(255,SUMPRODUCT(Sheet1!C10:E12,$B$2:$D$4))) -> 0 | H4: =MAX(0,MIN(255,SUMPRODUCT(Sheet1!D10:F12,$B$2:$D$4))) -> 0 | I4: =MAX(0,MIN(255,SUMPRODUCT(Sheet1!E10:G12,$B$2:$D$4))) -> 0 | J4: =MAX(0,MIN(255,SUMPRODUCT(Sheet1!F10:H12,$B$2:$D$4))) -> 0 | K4: =MAX(0,MIN(255,SUMPRODUCT(Sheet1!G10:I12,$B$2:$D$4))) -> 0 | L4: =MAX(0,MIN(255,SUMPRODUCT(Sheet1!H10:J12,$B$2:$D$4))) -> 0 | M4: =MAX(0,MIN(255,SUMPRODUCT(Sheet1!I10:K12,$B$2:$D$4))) -> 0 | N4: =MAX(0,MIN(255,SUMPRODUCT(Sheet1!J10:L12,$B$2:$D$4))) -> 0 | ... AH4: =MAX(0,MIN(255,SUMPRODUCT(Sheet1!AD10:AF12,$B$2:$D$4))) -> 0
G5: =MAX(0,MIN(255,SUMPRODUCT(Sheet1!C11:E13,$B$2:$D$4))) -> 0 | H5: =MAX(0,MIN(255,SUMPRODUCT(Sheet1!D11:F13,$B$2:$D$4))) -> 0 | I5: =MAX(0,MIN(255,SUMPRODUCT(Sheet1!E11:G13,$B$2:$D$4))) -> 0 | J5: =MAX(0,MIN(255,SUMPRODUCT(Sheet1!F11:H13,$B$2:$D$4))) -> 0 | K5: =MAX(0,MIN(255,SUMPRODUCT(Sheet1!G11:I13,$B$2:$D$4))) -> 0 | L5: =MAX(0,MIN(255,SUMPRODUCT(Sheet1!H11:J13,$B$2:$D$4))) -> 0 | M5: =MAX(0,MIN(255,SUMPRODUCT(Sheet1!I11:K13,$B$2:$D$4))) -> 0 | N5: =MAX(0,MIN(255,SUMPRODUCT(Sheet1!J11:L13,$B$2:$D$4))) -> 0 | ... AH5: =MAX(0,MIN(255,SUMPRODUCT(Sheet1!AD11:AF13,$B$2:$D$4))) -> 0
B6: 0.1111 | C6: 0.1111 | D6: 0.1111 | G6: =MAX(0,MIN(255,SUMPRODUCT(Sheet1!C12:E14,$B$2:$D$4))) -> 0 | H6: =MAX(0,MIN(255,SUMPRODUCT(Sheet1!D12:F14,$B$2:$D$4))) -> 0 | I6: =MAX(0,MIN(255,SUMPRODUCT(Sheet1!E12:G14,$B$2:$D$4))) -> 0 | J6: =MAX(0,MIN(255,SUMPRODUCT(Sheet1!F12:H14,$B$2:$D$4))) -> 0 | K6: =MAX(0,MIN(255,SUMPRODUCT(Sheet1!G12:I14,$B$2:$D$4))) -> 0 | L6: =MAX(0,MIN(255,SUMPRODUCT(Sheet1!H12:J14,$B$2:$D$4))) -> 0 | M6: =MAX(0,MIN(255,SUMPRODUCT(Sheet1!I12:K14,$B$2:$D$4))) -> 0 | N6: =MAX(0,MIN(255,SUMPRODUCT(Sheet1!J12:L14,$B$2:$D$4))) -> 0 | ... AH6: =MAX(0,MIN(255,SUMPRODUCT(Sheet1!AD12:AF14,$B$2:$D$4))) -> 0
B7: 0.1111 | C7: 0.1111 | D7: 0.1111 | G7: =MAX(0,MIN(255,SUMPRODUCT(Sheet1!C13:E15,$B$2:$D$4))) -> 0 | H7: =MAX(0,MIN(255,SUMPRODUCT(Sheet1!D13:F15,$B$2:$D$4))) -> 0 | I7: =MAX(0,MIN(255,SUMPRODUCT(Sheet1!E13:G15,$B$2:$D$4))) -> 0 | J7: =MAX(0,MIN(255,SUMPRODUCT(Sheet1!F13:H15,$B$2:$D$4))) -> 0 | K7: =MAX(0,MIN(255,SUMPRODUCT(Sheet1!G13:I15,$B$2:$D$4))) -> 255 | L7: =MAX(0,MIN(255,SUMPRODUCT(Sheet1!H13:J15,$B$2:$D$4))) -> 0 | M7: =MAX(0,MIN(255,SUMPRODUCT(Sheet1!I13:K15,$B$2:$D$4))) -> 0 | N7: =MAX(0,MIN(255,SUMPRODUCT(Sheet1!J13:L15,$B$2:$D$4))) -> 0 | ... AH7: =MAX(0,MIN(255,SUMPRODUCT(Sheet1!AD13:AF15,$B$2:$D$4))) -> 0
B8: 0.1111 | C8: 0.1111 | D8: 0.1111 | G8: =MAX(0,MIN(255,SUMPRODUCT(Sheet1!C14:E16,$B$2:$D$4))) -> 0 | H8: =MAX(0,MIN(255,SUMPRODUCT(Sheet1!D14:F16,$B$2:$D$4))) -> 0 | I8: =MAX(0,MIN(255,SUMPRODUCT(Sheet1!E14:G16,$B$2:$D$4))) -> 0 | J8: =MAX(0,MIN(255,SUMPRODUCT(Sheet1!F14:H16,$B$2:$D$4))) -> 255 | K8: =MAX(0,MIN(255,SUMPRODUCT(Sheet1!G14:I16,$B$2:$D$4))) -> 255 | L8: =MAX(0,MIN(255,SUMPRODUCT(Sheet1!H14:J16,$B$2:$D$4))) -> 0 | M8: =MAX(0,MIN(255,SUMPRODUCT(Sheet1!I14:K16,$B$2:$D$4))) -> 0 | N8: =MAX(0,MIN(255,SUMPRODUCT(Sheet1!J14:L16,$B$2:$D$4))) -> 0 | ... AH8: =MAX(0,MIN(255,SUMPRODUCT(Sheet1!AD14:AF16,$B$2:$D$4))) -> 0
G9: =MAX(0,MIN(255,SUMPRODUCT(Sheet1!C15:E17,$B$2:$D$4))) -> 0 | H9: =MAX(0,MIN(255,SUMPRODUCT(Sheet1!D15:F17,$B$2:$D$4))) -> 0 | I9: =MAX(0,MIN(255,SUMPRODUCT(Sheet1!E15:G17,$B$2:$D$4))) -> 255 | J9: =MAX(0,MIN(255,SUMPRODUCT(Sheet1!F15:H17,$B$2:$D$4))) -> 255 | K9: =MAX(0,MIN(255,SUMPRODUCT(Sheet1!G15:I17,$B$2:$D$4))) -> 0 | L9: =MAX(0,MIN(255,SUMPRODUCT(Sheet1!H15:J17,$B$2:$D$4))) -> 0 | M9: =MAX(0,MIN(255,SUMPRODUCT(Sheet1!I15:K17,$B$2:$D$4))) -> 0 | N9: =MAX(0,MIN(255,SUMPRODUCT(Sheet1!J15:L17,$B$2:$D$4))) -> 0 | ... AH9: =MAX(0,MIN(255,SUMPRODUCT(Sheet1!AD15:AF17,$B$2:$D$4))) -> 0
B10: -1 | C10: -2 | D10: -1 | G10: =MAX(0,MIN(255,SUMPRODUCT(Sheet1!C16:E18,$B$2:$D$4))) -> 0 | H10: =MAX(0,MIN(255,SUMPRODUCT(Sheet1!D16:F18,$B$2:$D$4))) -> 255 | I10: =MAX(0,MIN(255,SUMPRODUCT(Sheet1!E16:G18,$B$2:$D$4))) -> 255 | J10: =MAX(0,MIN(255,SUMPRODUCT(Sheet1!F16:H18,$B$2:$D$4))) -> 0 | K10: =MAX(0,MIN(255,SUMPRODUCT(Sheet1!G16:I18,$B$2:$D$4))) -> 0 | L10: =MAX(0,MIN(255,SUMPRODUCT(Sheet1!H16:J18,$B$2:$D$4))) -> 0 | M10: =MAX(0,MIN(255,SUMPRODUCT(Sheet1!I16:K18,$B$2:$D$4))) -> 255 | N10: =MAX(0,MIN(255,SUMPRODUCT(Sheet1!J16:L18,$B$2:$D$4))) -> 0 | ... AH10: =MAX(0,MIN(255,SUMPRODUCT(Sheet1!AD16:AF18,$B$2:$D$4))) -> 0
B11: 0 | C11: 0 | D11: 0 | G11: =MAX(0,MIN(255,SUMPRODUCT(Sheet1!C17:E19,$B$2:$D$4))) -> 255 | H11: =MAX(0,MIN(255,SUMPRODUCT(Sheet1!D17:F19,$B$2:$D$4))) -> 255 | I11: =MAX(0,MIN(255,SUMPRODUCT(Sheet1!E17:G19,$B$2:$D$4))) -> 0 | J11: =MAX(0,MIN(255,SUMPRODUCT(Sheet1!F17:H19,$B$2:$D$4))) -> 0 | K11: =MAX(0,MIN(255,SUMPRODUCT(Sheet1!G17:I19,$B$2:$D$4))) -> 0 | L11: =MAX(0,MIN(255,SUMPRODUCT(Sheet1!H17:J19,$B$2:$D$4))) -> 0 | M11: =MAX(0,MIN(255,SUMPRODUCT(Sheet1!I17:K19,$B$2:$D$4))) -> 255 | N11: =MAX(0,MIN(255,SUMPRODUCT(Sheet1!J17:L19,$B$2:$D$4))) -> 255 | ... AH11: =MAX(0,MIN(255,SUMPRODUCT(Sheet1!AD17:AF19,$B$2:$D$4))) -> 0
B12: 1 | C12: 2 | D12: 1 | G12: =MAX(0,MIN(255,SUMPRODUCT(Sheet1!C18:E20,$B$2:$D$4))) -> 255 | H12: =MAX(0,MIN(255,SUMPRODUCT(Sheet1!D18:F20,$B$2:$D$4))) -> 0 | I12: =MAX(0,MIN(255,SUMPRODUCT(Sheet1!E18:G20,$B$2:$D$4))) -> 0 | J12: =MAX(0,MIN(255,SUMPRODUCT(Sheet1!F18:H20,$B$2:$D$4))) -> 0 | K12: =MAX(0,MIN(255,SUMPRODUCT(Sheet1!G18:I20,$B$2:$D$4))) -> 0 | L12: =MAX(0,MIN(255,SUMPRODUCT(Sheet1!H18:J20,$B$2:$D$4))) -> 0 | M12: =MAX(0,MIN(255,SUMPRODUCT(Sheet1!I18:K20,$B$2:$D$4))) -> 0 | N12: =MAX(0,MIN(255,SUMPRODUCT(Sheet1!J18:L20,$B$2:$D$4))) -> 255 | ... AH12: =MAX(0,MIN(255,SUMPRODUCT(Sheet1!AD18:AF20,$B$2:$D$4))) -> 0
G13: =MAX(0,MIN(255,SUMPRODUCT(Sheet1!C19:E21,$B$2:$D$4))) -> 255 | H13: =MAX(0,MIN(255,SUMPRODUCT(Sheet1!D19:F21,$B$2:$D$4))) -> 0 | I13: =MAX(0,MIN(255,SUMPRODUCT(Sheet1!E19:G21,$B$2:$D$4))) -> 0 | J13: =MAX(0,MIN(255,SUMPRODUCT(Sheet1!F19:H21,$B$2:$D$4))) -> 0 | K13: =MAX(0,MIN(255,SUMPRODUCT(Sheet1!G19:I21,$B$2:$D$4))) -> 0 | L13: =MAX(0,MIN(255,SUMPRODUCT(Sheet1!H19:J21,$B$2:$D$4))) -> 0 | M13: =MAX(0,MIN(255,SUMPRODUCT(Sheet1!I19:K21,$B$2:$D$4))) -> 0 | N13: =MAX(0,MIN(255,SUMPRODUCT(Sheet1!J19:L21,$B$2:$D$4))) -> 0 | ... AH13: =MAX(0,MIN(255,SUMPRODUCT(Sheet1!AD19:AF21,$B$2:$D$4))) -> 0
B14: -1 | C14: 0 | D14: 1 | G14: =MAX(0,MIN(255,SUMPRODUCT(Sheet1!C20:E22,$B$2:$D$4))) -> 255 | H14: =MAX(0,MIN(255,SUMPRODUCT(Sheet1!D20:F22,$B$2:$D$4))) -> 0 | I14: =MAX(0,MIN(255,SUMPRODUCT(Sheet1!E20:G22,$B$2:$D$4))) -> 0 | J14: =MAX(0,MIN(255,SUMPRODUCT(Sheet1!F20:H22,$B$2:$D$4))) -> 0 | K14: =MAX(0,MIN(255,SUMPRODUCT(Sheet1!G20:I22,$B$2:$D$4))) -> 0 | L14: =MAX(0,MIN(255,SUMPRODUCT(Sheet1!H20:J22,$B$2:$D$4))) -> 0 | M14: =MAX(0,MIN(255,SUMPRODUCT(Sheet1!I20:K22,$B$2:$D$4))) -> 0 | N14: =MAX(0,MIN(255,SUMPRODUCT(Sheet1!J20:L22,$B$2:$D$4))) -> 255 | ... AH14: =MAX(0,MIN(255,SUMPRODUCT(Sheet1!AD20:AF22,$B$2:$D$4))) -> 0
B15: -2 | C15: 0 | D15: 2 | G15: =MAX(0,MIN(255,SUMPRODUCT(Sheet1!C21:E23,$B$2:$D$4))) -> 0 | H15: =MAX(0,MIN(255,SUMPRODUCT(Sheet1!D21:F23,$B$2:$D$4))) -> 0 | I15: =MAX(0,MIN(255,SUMPRODUCT(Sheet1!E21:G23,$B$2:$D$4))) -> 0 | J15: =MAX(0,MIN(255,SUMPRODUCT(Sheet1!F21:H23,$B$2:$D$4))) -> 0 | K15: =MAX(0,MIN(255,SUMPRODUCT(Sheet1!G21:I23,$B$2:$D$4))) -> 0 | L15: =MAX(0,MIN(255,SUMPRODUCT(Sheet1!H21:J23,$B$2:$D$4))) -> 0 | M15: =MAX(0,MIN(255,SUMPRODUCT(Sheet1!I21:K23,$B$2:$D$4))) -> 0 | N15: =MAX(0,MIN(255,SUMPRODUCT(Sheet1!J21:L23,$B$2:$D$4))) -> 255 | ... AH15: =MAX(0,MIN(255,SUMPRODUCT(Sheet1!AD21:AF23,$B$2:$D$4))) -> 0
B16: -1 | C16: 0 | D16: 1 | G16: =MAX(0,MIN(255,SUMPRODUCT(Sheet1!C22:E24,$B$2:$D$4))) -> 0 | H16: =MAX(0,MIN(255,SUMPRODUCT(Sheet1!D22:F24,$B$2:$D$4))) -> 0 | I16: =MAX(0,MIN(255,SUMPRODUCT(Sheet1!E22:G24,$B$2:$D$4))) -> 0 | J16: =MAX(0,MIN(255,SUMPRODUCT(Sheet1!F22:H24,$B$2:$D$4))) -> 255 | K16: =MAX(0,MIN(255,SUMPRODUCT(Sheet1!G22:I24,$B$2:$D$4))) -> 0 | L16: =MAX(0,MIN(255,SUMPRODUCT(Sheet1!H22:J24,$B$2:$D$4))) -> 0 | M16: =MAX(0,MIN(255,SUMPRODUCT(Sheet1!I22:K24,$B$2:$D$4))) -> 255 | N16: =MAX(0,MIN(255,SUMPRODUCT(Sheet1!J22:L24,$B$2:$D$4))) -> 255 | ... AH16: =MAX(0,MIN(255,SUMPRODUCT(Sheet1!AD22:AF24,$B$2:$D$4))) -> 0
G17: =MAX(0,MIN(255,SUMPRODUCT(Sheet1!C23:E25,$B$2:$D$4))) -> 0 | H17: =MAX(0,MIN(255,SUMPRODUCT(Sheet1!D23:F25,$B$2:$D$4))) -> 0 | I17: =MAX(0,MIN(255,SUMPRODUCT(Sheet1!E23:G25,$B$2:$D$4))) -> 0 | J17: =MAX(0,MIN(255,SUMPRODUCT(Sheet1!F23:H25,$B$2:$D$4))) -> 255 | K17: =MAX(0,MIN(255,SUMPRODUCT(Sheet1!G23:I25,$B$2:$D$4))) -> 0 | L17: =MAX(0,MIN(255,SUMPRODUCT(Sheet1!H23:J25,$B$2:$D$4))) -> 0 | M17: =MAX(0,MIN(255,SUMPRODUCT(Sheet1!I23:K25,$B$2:$D$4))) -> 255 | N17: =MAX(0,MIN(255,SUMPRODUCT(Sheet1!J23:L25,$B$2:$D$4))) -> 255 | ... AH17: =MAX(0,MIN(255,SUMPRODUCT(Sheet1!AD23:AF25,$B$2:$D$4))) -> 0
B18: -1 | C18: -1 | D18: -1 | G18: =MAX(0,MIN(255,SUMPRODUCT(Sheet1!C24:E26,$B$2:$D$4))) -> 0 | H18: =MAX(0,MIN(255,SUMPRODUCT(Sheet1!D24:F26,$B$2:$D$4))) -> 0 | I18: =MAX(0,MIN(255,SUMPRODUCT(Sheet1!E24:G26,$B$2:$D$4))) -> 0 | J18: =MAX(0,MIN(255,SUMPRODUCT(Sheet1!F24:H26,$B$2:$D$4))) -> 255 | K18: =MAX(0,MIN(255,SUMPRODUCT(Sheet1!G24:I26,$B$2:$D$4))) -> 0 | L18: =MAX(0,MIN(255,SUMPRODUCT(Sheet1!H24:J26,$B$2:$D$4))) -> 0 | M18: =MAX(0,MIN(255,SUMPRODUCT(Sheet1!I24:K26,$B$2:$D$4))) -> 255 | N18: =MAX(0,MIN(255,SUMPRODUCT(Sheet1!J24:L26,$B$2:$D$4))) -> 255 | ... AH18: =MAX(0,MIN(255,SUMPRODUCT(Sheet1!AD24:AF26,$B$2:$D$4))) -> 0
B19: 0 | C19: 0 | D19: 0 | G19: =MAX(0,MIN(255,SUMPRODUCT(Sheet1!C25:E27,$B$2:$D$4))) -> 0 | H19: =MAX(0,MIN(255,SUMPRODUCT(Sheet1!D25:F27,$B$2:$D$4))) -> 0 | I19: =MAX(0,MIN(255,SUMPRODUCT(Sheet1!E25:G27,$B$2:$D$4))) -> 0 | J19: =MAX(0,MIN(255,SUMPRODUCT(Sheet1!F25:H27,$B$2:$D$4))) -> 255 | K19: =MAX(0,MIN(255,SUMPRODUCT(Sheet1!G25:I27,$B$2:$D$4))) -> 0 | L19: =MAX(0,MIN(255,SUMPRODUCT(Sheet1!H25:J27,$B$2:$D$4))) -> 0 | M19: =MAX(0,MIN(255,SUMPRODUCT(Sheet1!I25:K27,$B$2:$D$4))) -> 255 | N19: =MAX(0,MIN(255,SUMPRODUCT(Sheet1!J25:L27,$B$2:$D$4))) -> 255 | ... AH19: =MAX(0,MIN(255,SUMPRODUCT(Sheet1!AD25:AF27,$B$2:$D$4))) -> 0
B20: 1 | C20: 1 | D20: 1 | G20: =MAX(0,MIN(255,SUMPRODUCT(Sheet1!C26:E28,$B$2:$D$4))) -> 0 | H20: =MAX(0,MIN(255,SUMPRODUCT(Sheet1!D26:F28,$B$2:$D$4))) -> 0 | I20: =MAX(0,MIN(255,SUMPRODUCT(Sheet1!E26:G28,$B$2:$D$4))) -> 0 | J20: =MAX(0,MIN(255,SUMPRODUCT(Sheet1!F26:H28,$B$2:$D$4))) -> 255 | K20: =MAX(0,MIN(255,SUMPRODUCT(Sheet1!G26:I28,$B$2:$D$4))) -> 0 | L20: =MAX(0,MIN(255,SUMPRODUCT(Sheet1!H26:J28,$B$2:$D$4))) -> 0 | M20: =MAX(0,MIN(255,SUMPRODUCT(Sheet1!I26:K28,$B$2:$D$4))) -> 255 | N20: =MAX(0,MIN(255,SUMPRODUCT(Sheet1!J26:L28,$B$2:$D$4))) -> 0 | ... AH20: =MAX(0,MIN(255,SUMPRODUCT(Sheet1!AD26:AF28,$B$2:$D$4))) -> 0
G21: =MAX(0,MIN(255,SUMPRODUCT(Sheet1!C27:E29,$B$2:$D$4))) -> 0 | H21: =MAX(0,MIN(255,SUMPRODUCT(Sheet1!D27:F29,$B$2:$D$4))) -> 0 | I21: =MAX(0,MIN(255,SUMPRODUCT(Sheet1!E27:G29,$B$2:$D$4))) -> 0 | J21: =MAX(0,MIN(255,SUMPRODUCT(Sheet1!F27:H29,$B$2:$D$4))) -> 255 | K21: =MAX(0,MIN(255,SUMPRODUCT(Sheet1!G27:I29,$B$2:$D$4))) -> 0 | L21: =MAX(0,MIN(255,SUMPRODUCT(Sheet1!H27:J29,$B$2:$D$4))) -> 0 | M21: =MAX(0,MIN(255,SUMPRODUCT(Sheet1!I27:K29,$B$2:$D$4))) -> 255 | N21: =MAX(0,MIN(255,SUMPRODUCT(Sheet1!J27:L29,$B$2:$D$4))) -> 0 | ... AH21: =MAX(0,MIN(255,SUMPRODUCT(Sheet1!AD27:AF29,$B$2:$D$4))) -> 0
B22: -1 | C22: 0 | D22: 1 | G22: =MAX(0,MIN(255,SUMPRODUCT(Sheet1!C28:E30,$B$2:$D$4))) -> 0 | H22: =MAX(0,MIN(255,SUMPRODUCT(Sheet1!D28:F30,$B$2:$D$4))) -> 0 | I22: =MAX(0,MIN(255,SUMPRODUCT(Sheet1!E28:G30,$B$2:$D$4))) -> 0 | J22: =MAX(0,MIN(255,SUMPRODUCT(Sheet1!F28:H30,$B$2:$D$4))) -> 255 | K22: =MAX(0,MIN(255,SUMPRODUCT(Sheet1!G28:I30,$B$2:$D$4))) -> 0 | L22: =MAX(0,MIN(255,SUMPRODUCT(Sheet1!H28:J30,$B$2:$D$4))) -> 0 | M22: =MAX(0,MIN(255,SUMPRODUCT(Sheet1!I28:K30,$B$2:$D$4))) -> 255 | N22: =MAX(0,MIN(255,SUMPRODUCT(Sheet1!J28:L30,$B$2:$D$4))) -> 0 | ... AH22: =MAX(0,MIN(255,SUMPRODUCT(Sheet1!AD28:AF30,$B$2:$D$4))) -> 0
B23: -1 | C23: 0 | D23: 1 | G23: =MAX(0,MIN(255,SUMPRODUCT(Sheet1!C29:E31,$B$2:$D$4))) -> 0 | H23: =MAX(0,MIN(255,SUMPRODUCT(Sheet1!D29:F31,$B$2:$D$4))) -> 0 | I23: =MAX(0,MIN(255,SUMPRODUCT(Sheet1!E29:G31,$B$2:$D$4))) -> 0 | J23: =MAX(0,MIN(255,SUMPRODUCT(Sheet1!F29:H31,$B$2:$D$4))) -> 255 | K23: =MAX(0,MIN(255,SUMPRODUCT(Sheet1!G29:I31,$B$2:$D$4))) -> 0 | L23: =MAX(0,MIN(255,SUMPRODUCT(Sheet1!H29:J31,$B$2:$D$4))) -> 0 | M23: =MAX(0,MIN(255,SUMPRODUCT(Sheet1!I29:K31,$B$2:$D$4))) -> 0 | N23: =MAX(0,MIN(255,SUMPRODUCT(Sheet1!J29:L31,$B$2:$D$4))) -> 0 | ... AH23: =MAX(0,MIN(255,SUMPRODUCT(Sheet1!AD29:AF31,$B$2:$D$4))) -> 0
B24: -1 | C24: 0 | D24: 1 | G24: =MAX(0,MIN(255,SUMPRODUCT(Sheet1!C30:E32,$B$2:$D$4))) -> 0 | H24: =MAX(0,MIN(255,SUMPRODUCT(Sheet1!D30:F32,$B$2:$D$4))) -> 0 | I24: =MAX(0,MIN(255,SUMPRODUCT(Sheet1!E30:G32,$B$2:$D$4))) -> 0 | J24: =MAX(0,MIN(255,SUMPRODUCT(Sheet1!F30:H32,$B$2:$D$4))) -> 255 | K24: =MAX(0,MIN(255,SUMPRODUCT(Sheet1!G30:I32,$B$2:$D$4))) -> 0 | L24: =MAX(0,MIN(255,SUMPRODUCT(Sheet1!H30:J32,$B$2:$D$4))) -> 0 | M24: =MAX(0,MIN(255,SUMPRODUCT(Sheet1!I30:K32,$B$2:$D$4))) -> 0 | N24: =MAX(0,MIN(255,SUMPRODUCT(Sheet1!J30:L32,$B$2:$D$4))) -> 0 | ... AH24: =MAX(0,MIN(255,SUMPRODUCT(Sheet1!AD30:AF32,$B$2:$D$4))) -> 0
G25: =MAX(0,MIN(255,SUMPRODUCT(Sheet1!C31:E33,$B$2:$D$4))) -> 0 | H25: =MAX(0,MIN(255,SUMPRODUCT(Sheet1!D31:F33,$B$2:$D$4))) -> 0 | I25: =MAX(0,MIN(255,SUMPRODUCT(Sheet1!E31:G33,$B$2:$D$4))) -> 0 | J25: =MAX(0,MIN(255,SUMPRODUCT(Sheet1!F31:H33,$B$2:$D$4))) -> 255 | K25: =MAX(0,MIN(255,SUMPRODUCT(Sheet1!G31:I33,$B$2:$D$4))) -> 0 | L25: =MAX(0,MIN(255,SUMPRODUCT(Sheet1!H31:J33,$B$2:$D$4))) -> 0 | M25: =MAX(0,MIN(255,SUMPRODUCT(Sheet1!I31:K33,$B$2:$D$4))) -> 0 | N25: =MAX(0,MIN(255,SUMPRODUCT(Sheet1!J31:L33,$B$2:$D$4))) -> 0 | ... AH25: =MAX(0,MIN(255,SUMPRODUCT(Sheet1!AD31:AF33,$B$2:$D$4))) -> 0
B26: 0 | C26: 1 | D26: 0 | G26: =MAX(0,MIN(255,SUMPRODUCT(Sheet1!C32:E34,$B$2:$D$4))) -> 0 | H26: =MAX(0,MIN(255,SUMPRODUCT(Sheet1!D32:F34,$B$2:$D$4))) -> 0 | I26: =MAX(0,MIN(255,SUMPRODUCT(Sheet1!E32:G34,$B$2:$D$4))) -> 0 | J26: =MAX(0,MIN(255,SUMPRODUCT(Sheet1!F32:H34,$B$2:$D$4))) -> 255 | K26: =MAX(0,MIN(255,SUMPRODUCT(Sheet1!G32:I34,$B$2:$D$4))) -> 0 | L26: =MAX(0,MIN(255,SUMPRODUCT(Sheet1!H32:J34,$B$2:$D$4))) -> 0 | M26: =MAX(0,MIN(255,SUMPRODUCT(Sheet1!I32:K34,$B$2:$D$4))) -> 0 | N26: =MAX(0,MIN(255,SUMPRODUCT(Sheet1!J32:L34,$B$2:$D$4))) -> 0 | ... AH26: =MAX(0,MIN(255,SUMPRODUCT(Sheet1!AD32:AF34,$B$2:$D$4))) -> 0
B27: 1 | C27: -4 | D27: 1 | G27: =MAX(0,MIN(255,SUMPRODUCT(Sheet1!C33:E35,$B$2:$D$4))) -> 0 | H27: =MAX(0,MIN(255,SUMPRODUCT(Sheet1!D33:F35,$B$2:$D$4))) -> 0 | I27: =MAX(0,MIN(255,SUMPRODUCT(Sheet1!E33:G35,$B$2:$D$4))) -> 0 | J27: =MAX(0,MIN(255,SUMPRODUCT(Sheet1!F33:H35,$B$2:$D$4))) -> 255 | K27: =MAX(0,MIN(255,SUMPRODUCT(Sheet1!G33:I35,$B$2:$D$4))) -> 0 | L27: =MAX(0,MIN(255,SUMPRODUCT(Sheet1!H33:J35,$B$2:$D$4))) -> 0 | M27: =MAX(0,MIN(255,SUMPRODUCT(Sheet1!I33:K35,$B$2:$D$4))) -> 0 | N27: =MAX(0,MIN(255,SUMPRODUCT(Sheet1!J33:L35,$B$2:$D$4))) -> 0 | ... AH27: =MAX(0,MIN(255,SUMPRODUCT(Sheet1!AD33:AF35,$B$2:$D$4))) -> 0
B28: 0 | C28: 1 | D28: 0 | G28: =MAX(0,MIN(255,SUMPRODUCT(Sheet1!C34:E36,$B$2:$D$4))) -> 0 | H28: =MAX(0,MIN(255,SUMPRODUCT(Sheet1!D34:F36,$B$2:$D$4))) -> 0 | I28: =MAX(0,MIN(255,SUMPRODUCT(Sheet1!E34:G36,$B$2:$D$4))) -> 0 | J28: =MAX(0,MIN(255,SUMPRODUCT(Sheet1!F34:H36,$B$2:$D$4))) -> 255 | K28: =MAX(0,MIN(255,SUMPRODUCT(Sheet1!G34:I36,$B$2:$D$4))) -> 0 | L28: =MAX(0,MIN(255,SUMPRODUCT(Sheet1!H34:J36,$B$2:$D$4))) -> 0 | M28: =MAX(0,MIN(255,SUMPRODUCT(Sheet1!I34:K36,$B$2:$D$4))) -> 0 | N28: =MAX(0,MIN(255,SUMPRODUCT(Sheet1!J34:L36,$B$2:$D$4))) -> 0 | ... AH28: =MAX(0,MIN(255,SUMPRODUCT(Sheet1!AD34:AF36,$B$2:$D$4))) -> 0
G29: =MAX(0,MIN(255,SUMPRODUCT(Sheet1!C35:E37,$B$2:$D$4))) -> 0 | H29: =MAX(0,MIN(255,SUMPRODUCT(Sheet1!D35:F37,$B$2:$D$4))) -> 0 | I29: =MAX(0,MIN(255,SUMPRODUCT(Sheet1!E35:G37,$B$2:$D$4))) -> 0 | J29: =MAX(0,MIN(255,SUMPRODUCT(Sheet1!F35:H37,$B$2:$D$4))) -> 255 | K29: =MAX(0,MIN(255,SUMPRODUCT(Sheet1!G35:I37,$B$2:$D$4))) -> 0 | L29: =MAX(0,MIN(255,SUMPRODUCT(Sheet1!H35:J37,$B$2:$D$4))) -> 0 | M29: =MAX(0,MIN(255,SUMPRODUCT(Sheet1!I35:K37,$B$2:$D$4))) -> 0 | N29: =MAX(0,MIN(255,SUMPRODUCT(Sheet1!J35:L37,$B$2:$D$4))) -> 0 | ... AH29: =MAX(0,MIN(255,SUMPRODUCT(Sheet1!AD35:AF37,$B$2:$D$4))) -> 0
B30: 1 | C30: 1 | D30: 1
B31: 1 | C31: -8 | D31: 1
B32: 1 | C32: 1 | D32: 1
B34: 0 | C34: -1 | D34: 0
B35: -1 | C35: 5 | D35: -1
B36: 0 | C36: -1 | D36: 0
B38: 1 | C38: 1 | D38: 1
B39: 0 | C39: 0 | D39: 0
B40: -1 | C40: -1 | D40: -1
B42: 1 | C42: 0 | D42: -1
B43: 1 | C43: 0 | D43: -1
...
